[2025-02-25T11:08:58.864+0000] {local_task_job_runner.py:123} INFO - ::group::Pre task execution logs
[2025-02-25T11:08:58.882+0000] {taskinstance.py:2614} INFO - Dependencies all met for dep_context=non-requeueable deps ti=<TaskInstance: emissionAI_ml_pipeline.ingest_data manual__2025-02-25T11:03:48.164108+00:00 [queued]>
[2025-02-25T11:08:58.894+0000] {taskinstance.py:2614} INFO - Dependencies all met for dep_context=requeueable deps ti=<TaskInstance: emissionAI_ml_pipeline.ingest_data manual__2025-02-25T11:03:48.164108+00:00 [queued]>
[2025-02-25T11:08:58.896+0000] {taskinstance.py:2867} INFO - Starting attempt 2 of 2
[2025-02-25T11:08:58.913+0000] {taskinstance.py:2890} INFO - Executing <Task(_PythonDecoratedOperator): ingest_data> on 2025-02-25 11:03:48.164108+00:00
[2025-02-25T11:08:58.919+0000] {standard_task_runner.py:72} INFO - Started process 393 to run task
[2025-02-25T11:08:58.924+0000] {standard_task_runner.py:104} INFO - Running: ['airflow', 'tasks', 'run', 'emissionAI_ml_pipeline', 'ingest_data', 'manual__2025-02-25T11:03:48.164108+00:00', '--job-id', '74', '--raw', '--subdir', 'DAGS_FOLDER/ml_pipeline.py', '--cfg-path', '/tmp/tmph1c1sx8l']
[2025-02-25T11:08:58.928+0000] {standard_task_runner.py:105} INFO - Job 74: Subtask ingest_data
[2025-02-25T11:08:58.992+0000] {task_command.py:467} INFO - Running <TaskInstance: emissionAI_ml_pipeline.ingest_data manual__2025-02-25T11:03:48.164108+00:00 [running]> on host 1f0a2691b33e
[2025-02-25T11:08:59.098+0000] {taskinstance.py:3134} INFO - Exporting env vars: AIRFLOW_CTX_DAG_OWNER='airflow' AIRFLOW_CTX_DAG_ID='emissionAI_ml_pipeline' AIRFLOW_CTX_TASK_ID='ingest_data' AIRFLOW_CTX_EXECUTION_DATE='2025-02-25T11:03:48.164108+00:00' AIRFLOW_CTX_TRY_NUMBER='2' AIRFLOW_CTX_DAG_RUN_ID='manual__2025-02-25T11:03:48.164108+00:00'
[2025-02-25T11:08:59.100+0000] {taskinstance.py:732} INFO - ::endgroup::
[2025-02-25T11:08:59.111+0000] {logging_mixin.py:190} INFO - host: aws-0-ap-southeast-1.pooler.supabase.com, user: postgres.yksdylbnseqxrbwaxmgz, pass: jtVHoVpDpfxOw0CI, db: postgres, port: 5432
[2025-02-25T11:08:59.113+0000] {data_ingestion.py:44} INFO - SQLAlchemy engine created successfully.
[2025-02-25T11:08:59.114+0000] {data_ingestion.py:60} INFO - Executing query to fetch data from table fuel_consumption_1995_2025.
[2025-02-25T11:09:08.818+0000] {data_ingestion.py:65} INFO - Loaded 28492 records from table.
[2025-02-25T11:09:08.823+0000] {data_ingestion.py:71} ERROR - Error fetching data from table fuel_consumption_1995_2025: Cannot save file into a non-existent directory: 'artifacts/data_ingestion/data'
[2025-02-25T11:09:08.824+0000] {taskinstance.py:3313} ERROR - Task failed with exception
Traceback (most recent call last):
  File "/opt/airflow/src/component/data_ingestion.py", line 68, in ingest_data_from_pg_db
    df.to_csv(data_save_path)
  File "/home/airflow/.local/lib/python3.9/site-packages/pandas/core/generic.py", line 3902, in to_csv
    return DataFrameRenderer(formatter).to_csv(
  File "/home/airflow/.local/lib/python3.9/site-packages/pandas/io/formats/format.py", line 1152, in to_csv
    csv_formatter.save()
  File "/home/airflow/.local/lib/python3.9/site-packages/pandas/io/formats/csvs.py", line 247, in save
    with get_handle(
  File "/home/airflow/.local/lib/python3.9/site-packages/pandas/io/common.py", line 739, in get_handle
    check_parent_directory(str(handle))
  File "/home/airflow/.local/lib/python3.9/site-packages/pandas/io/common.py", line 604, in check_parent_directory
    raise OSError(rf"Cannot save file into a non-existent directory: '{parent}'")
OSError: Cannot save file into a non-existent directory: 'artifacts/data_ingestion/data'

During handling of the above exception, another exception occurred:

Traceback (most recent call last):
  File "/home/airflow/.local/lib/python3.9/site-packages/airflow/models/taskinstance.py", line 768, in _execute_task
    result = _execute_callable(context=context, **execute_callable_kwargs)
  File "/home/airflow/.local/lib/python3.9/site-packages/airflow/models/taskinstance.py", line 734, in _execute_callable
    return ExecutionCallableRunner(
  File "/home/airflow/.local/lib/python3.9/site-packages/airflow/utils/operator_helpers.py", line 252, in run
    return self.func(*args, **kwargs)
  File "/home/airflow/.local/lib/python3.9/site-packages/airflow/models/baseoperator.py", line 424, in wrapper
    return func(self, *args, **kwargs)
  File "/home/airflow/.local/lib/python3.9/site-packages/airflow/decorators/base.py", line 266, in execute
    return_value = super().execute(context)
  File "/home/airflow/.local/lib/python3.9/site-packages/airflow/models/baseoperator.py", line 424, in wrapper
    return func(self, *args, **kwargs)
  File "/home/airflow/.local/lib/python3.9/site-packages/airflow/operators/python.py", line 238, in execute
    return_value = self.execute_callable()
  File "/home/airflow/.local/lib/python3.9/site-packages/airflow/operators/python.py", line 256, in execute_callable
    return runner.run(*self.op_args, **self.op_kwargs)
  File "/home/airflow/.local/lib/python3.9/site-packages/airflow/utils/operator_helpers.py", line 252, in run
    return self.func(*args, **kwargs)
  File "/opt/airflow/dags/ml_pipeline.py", line 36, in ingest_data
    data_ingestion.ingest_data_from_pg_db()
  File "/opt/airflow/src/component/data_ingestion.py", line 72, in ingest_data_from_pg_db
    raise CustomException(e, sys)
src.utils.exception.CustomException: Error occurred in python script name /opt/airflow/src/component/data_ingestion.py line number 68 error message Cannot save file into a non-existent directory: 'artifacts/data_ingestion/data'
[2025-02-25T11:09:08.849+0000] {taskinstance.py:1226} INFO - Marking task as FAILED. dag_id=emissionAI_ml_pipeline, task_id=ingest_data, run_id=manual__2025-02-25T11:03:48.164108+00:00, execution_date=20250225T110348, start_date=20250225T110858, end_date=20250225T110908
[2025-02-25T11:09:08.887+0000] {taskinstance.py:341} INFO - ::group::Post task execution logs
[2025-02-25T11:09:08.890+0000] {standard_task_runner.py:124} ERROR - Failed to execute job 74 for task ingest_data (Error occurred in python script name /opt/airflow/src/component/data_ingestion.py line number 68 error message Cannot save file into a non-existent directory: 'artifacts/data_ingestion/data'; 393)
Traceback (most recent call last):
  File "/opt/airflow/src/component/data_ingestion.py", line 68, in ingest_data_from_pg_db
    df.to_csv(data_save_path)
  File "/home/airflow/.local/lib/python3.9/site-packages/pandas/core/generic.py", line 3902, in to_csv
    return DataFrameRenderer(formatter).to_csv(
  File "/home/airflow/.local/lib/python3.9/site-packages/pandas/io/formats/format.py", line 1152, in to_csv
    csv_formatter.save()
  File "/home/airflow/.local/lib/python3.9/site-packages/pandas/io/formats/csvs.py", line 247, in save
    with get_handle(
  File "/home/airflow/.local/lib/python3.9/site-packages/pandas/io/common.py", line 739, in get_handle
    check_parent_directory(str(handle))
  File "/home/airflow/.local/lib/python3.9/site-packages/pandas/io/common.py", line 604, in check_parent_directory
    raise OSError(rf"Cannot save file into a non-existent directory: '{parent}'")
OSError: Cannot save file into a non-existent directory: 'artifacts/data_ingestion/data'

During handling of the above exception, another exception occurred:

Traceback (most recent call last):
  File "/home/airflow/.local/lib/python3.9/site-packages/airflow/task/task_runner/standard_task_runner.py", line 117, in _start_by_fork
    ret = args.func(args, dag=self.dag)
  File "/home/airflow/.local/lib/python3.9/site-packages/airflow/cli/cli_config.py", line 49, in command
    return func(*args, **kwargs)
  File "/home/airflow/.local/lib/python3.9/site-packages/airflow/utils/cli.py", line 116, in wrapper
    return f(*args, **kwargs)
  File "/home/airflow/.local/lib/python3.9/site-packages/airflow/cli/commands/task_command.py", line 483, in task_run
    task_return_code = _run_task_by_selected_method(args, _dag, ti)
  File "/home/airflow/.local/lib/python3.9/site-packages/airflow/cli/commands/task_command.py", line 256, in _run_task_by_selected_method
    return _run_raw_task(args, ti)
  File "/home/airflow/.local/lib/python3.9/site-packages/airflow/cli/commands/task_command.py", line 341, in _run_raw_task
    return ti._run_raw_task(
  File "/home/airflow/.local/lib/python3.9/site-packages/airflow/utils/session.py", line 97, in wrapper
    return func(*args, session=session, **kwargs)
  File "/home/airflow/.local/lib/python3.9/site-packages/airflow/models/taskinstance.py", line 3006, in _run_raw_task
    return _run_raw_task(
  File "/home/airflow/.local/lib/python3.9/site-packages/airflow/models/taskinstance.py", line 274, in _run_raw_task
    TaskInstance._execute_task_with_callbacks(
  File "/home/airflow/.local/lib/python3.9/site-packages/airflow/models/taskinstance.py", line 3161, in _execute_task_with_callbacks
    result = self._execute_task(context, task_orig)
  File "/home/airflow/.local/lib/python3.9/site-packages/airflow/models/taskinstance.py", line 3185, in _execute_task
    return _execute_task(self, context, task_orig)
  File "/home/airflow/.local/lib/python3.9/site-packages/airflow/models/taskinstance.py", line 768, in _execute_task
    result = _execute_callable(context=context, **execute_callable_kwargs)
  File "/home/airflow/.local/lib/python3.9/site-packages/airflow/models/taskinstance.py", line 734, in _execute_callable
    return ExecutionCallableRunner(
  File "/home/airflow/.local/lib/python3.9/site-packages/airflow/utils/operator_helpers.py", line 252, in run
    return self.func(*args, **kwargs)
  File "/home/airflow/.local/lib/python3.9/site-packages/airflow/models/baseoperator.py", line 424, in wrapper
    return func(self, *args, **kwargs)
  File "/home/airflow/.local/lib/python3.9/site-packages/airflow/decorators/base.py", line 266, in execute
    return_value = super().execute(context)
  File "/home/airflow/.local/lib/python3.9/site-packages/airflow/models/baseoperator.py", line 424, in wrapper
    return func(self, *args, **kwargs)
  File "/home/airflow/.local/lib/python3.9/site-packages/airflow/operators/python.py", line 238, in execute
    return_value = self.execute_callable()
  File "/home/airflow/.local/lib/python3.9/site-packages/airflow/operators/python.py", line 256, in execute_callable
    return runner.run(*self.op_args, **self.op_kwargs)
  File "/home/airflow/.local/lib/python3.9/site-packages/airflow/utils/operator_helpers.py", line 252, in run
    return self.func(*args, **kwargs)
  File "/opt/airflow/dags/ml_pipeline.py", line 36, in ingest_data
    data_ingestion.ingest_data_from_pg_db()
  File "/opt/airflow/src/component/data_ingestion.py", line 72, in ingest_data_from_pg_db
    raise CustomException(e, sys)
src.utils.exception.CustomException: Error occurred in python script name /opt/airflow/src/component/data_ingestion.py line number 68 error message Cannot save file into a non-existent directory: 'artifacts/data_ingestion/data'
[2025-02-25T11:09:08.922+0000] {local_task_job_runner.py:266} INFO - Task exited with return code 1
[2025-02-25T11:09:08.939+0000] {standard_task_runner.py:217} INFO - Process not found (most likely exited), stop collecting metrics
[2025-02-25T11:09:08.964+0000] {taskinstance.py:3901} INFO - 0 downstream tasks scheduled from follow-on schedule check
[2025-02-25T11:09:08.970+0000] {local_task_job_runner.py:245} INFO - ::endgroup::
